Workbook

Sheet All Subcamps
A1: No | B1: First name | C1: Last name | D1: Email | E1: Mobile phone | F1: Invoice details | G1: Country | H1: Scout Association | I1: Troop name | J1: Troop organisation number | K1: City | L1: Number of Children | M1: Number of Leaders | N1: Arrival day | O1: Arrival time | P1: Departure day | Q1: Departure time | R1: Further remarks (optional) | S1: Order Number | T1: Total Costs | U1: Payment Type | V1: Registration time | W1: Order Number2 | X1: Additional registrants | Y1: Comments RJ: | Z1: Subcamp
A2: 33 | B2: Joseph | C2: Monk | D2: joe.monk@britishscoutingoverseas.org.uk | E2: +32484266960 | G2: Belgium | H2: FOS Open Scouting | I2: Central Brussels Scouts | J2: 112e | K2: Brussels | L2: 15 | M2: 5 | N2: Friday | O2: 21:00 - 00:00 | P2: Monday | Q2: 15:00 - 18:00 | R2: Arrival and Departure times are estimates. 2 additional Scouters needed due to logistical requirements to transport youth and equipment. | S2: IST-18979 | T2: 500 | U2: Mollie | V2: 2024-12-02 09:42:04 | W2: 1733132524 | Z2: 2
A3: 30 | B3: Jonathan | C3: Copner | D3: jon.copner@britishscoutingoverseas.org.uk | E3: +32 | F3: Grootveldlaan 12, 3080 Tervuren, Belgium | G3: Belgium | H3: FOS Open Scouting | I3: Brussels Explorers | J3: FOS111 | K3: Tervuren | L3: 12 | M3: 3 | N3: Friday | O3: 18:00 - 21:00 | P3: Monday | Q3: 12:00 - 15:00 | R3: 3 leaders - 3 vehicles required | S3: IST-95976 | T3: 375 | U3: Mollie | V3: 2024-12-01 12:56:03 | W3: 1733057763 | Z3: 2
A4: 59 | B4: Barbora | C4: Jánská | D4: janskabarbora@gmail.com | E4: +420733650318 | G4: Czech Republic | H4: JUNAK - cesky skaut | I4: Dráčata Štěnovice | J4: 323.02 | K4: Štěnovice | L4: 20 | M4: 4 | N4: Friday | O4: 18:00 - 21:00 | P4: Monday | Q4: 09:00 - 12:00 | S4: IST-69112 | T4: 600 | U4: Mollie | V4: 2025-01-13 14:28:34 | W4: 1736778514 | Z4: 1
A5: 60 | B5: Martin | C5: Kolarik | D5: smurf@skaut.cz | E5: +420723923943 | F5: Junák – český skaut, středisko Járy Kaštila Prostějov, z. s. Sokolská 30, 796 01 Prostějov Czech republic IČO: 65762959 | G5: Czech Republic | H5: JUNAK - cesky skaut | I5: JK | J5: 713.05 | K5: Prostejov | L5: 20 | M5: 4 | N5: Friday | O5: 15:00 - 18:00 | P5: Monday | Q5: 09:00 - 12:00 | S5: IST-11762 | T5: 600 | U5: Mollie | V5: 2025-01-15 07:08:46 | W5: 1736924926 | Z5: 3
A6: 61 | B6: Pavel | C6: Šenkyřík | D6: 180.veneta@gmail.com | E6: +420733233486 | F6: Customer: Junák - český skaut, středisko Platan Praha, z. s. Adress: Viktorinova 1122/1,Praha 4 – Nusle, 140 00 Praha, Česká Republika IČO: 40613593 | G6: Czech Republic | H6: JUNAK - cesky skaut | I6: Platan | J6: 114.32 | K6: Prague | L6: 20 | M6: 3 | N6: Friday | O6: 18:00 - 21:00 | P6: Monday | Q6: 09:00 - 12:00 | S6: IST-32540 | T6: 575 | U6: Mollie | V6: 2025-01-18 14:39:42 | W6: 1737211182 | Z6: 3
A7: 62 | B7: Lenka | C7: Hechtová | D7: lenkalischkova@gmail.com | E7: +420607881402 | G7: Czech Republic | H7: JUNAK - cesky skaut | I7: Core | J7: 511.02.004 | K7: Nový Bor | L7: 20 | M7: 4 | N7: Friday | O7: 18:00 - 21:00 | P7: Monday | Q7: 09:00 - 12:00 | S7: IST-18688 | T7: 600 | U7: Mollie | V7: 2025-01-19 18:16:07 | W7: 1737310567 | Z7: 2
A8: 63 | B8: Petr | C8: Kvarda | D8: kvardic.p@seznam.cz | E8: +420739528720 | G8: Czech Republic | H8: JUNAK - cesky skaut | I8: Goliath | J8: 611.05 | K8: Přibyslav | L8: 8 | M8: 2 | N8: Friday | O8: 12:00 - 15:00 | P8: Monday | Q8: 15:00 - 18:00 | S8: IST-12285 | T8: 250 | U8: Mollie | V8: 2025-01-20 17:26:18 | W8: 1737393978 | Z8: 2
A9: 64 | B9: Klára | C9: Helánová | D9: akela.sebetov@skaut.cz | E9: +420777865883 | F9: Junák - Český skaut, středisko Severka, z.s. Šebetov 49 679 35 Czech Republic | G9: Czech Republic | H9: JUNAK - cesky skaut | I9: Středisko Severka | J9: 621.11 | K9: Šebetov | L9: 15 | M9: 3 | N9: Friday | O9: 15:00 - 18:00 | P9: Monday | Q9: 12:00 - 15:00 | R9: We are not sure about the arrival time yet. We're in the process of deciding between Friday morning (around 10 am) and evening (around 6 pm). We'll let you know once we've settled. | S9: IST-64335 | T9: 450 | U9: Mollie | V9: 2025-01-21 17:35:18 | W9: 1737480918 | Z9: 2
A10: 65 | B10: Jan | C10: Holoubek | D10: jan.holoubek@skaut.cz | E10: +420736149229 | G10: Czech Republic | H10: JUNAK - cesky skaut | I10: Stopa | J10: 526.06.004 | K10: Hradec Králové | L10: 6 | M10: 2 | N10: Friday | O10: 12:00 - 15:00 | P10: Monday | Q10: 09:00 - 12:00 | R10: We need to be two adults for safety reasons (two drivers). Also we both work with the troop during the year as mentors. | S10: IST-54674 | T10: 200 | U10: Mollie | V10: 2025-01-22 16:15:01 | W10: 1737562501 | Z10: 1
A11: 66 | B11: Vojtěch | C11: Podzimek | D11: podzimek.vojta@skaut.cz | E11: +420724144345 | F11: Junák - český skaut, středisko Sopka Nová Paka, z. s. Svatojánská 1193 509 01 Nová Paka IČ: 60116421 | G11: Czech Republic | H11: JUNAK - cesky skaut | I11: Sopka Nová Paka | J11: 522.03 | K11: NOVÁ PAKA | L11: 20 | M11: 4 | N11: Friday | O11: 18:00 - 21:00 | P11: Monday | Q11: 09:00 - 12:00 | S11: IST-16688 | T11: 600 | U11: Mollie | V11: 2025-01-22 20:56:18 | W11: 1737579378 | Z11: 1
A12: 67 | B12: Šimon | C12: Trousil | D12: simon.trousil@seznam.cz | E12: +420720103492 | G12: Czech Republic | H12: JUNAK - cesky skaut | I12: Orion Kladno | J12: 213.01 | K12: Kladno | L12: 18 | M12: 3 | N12: Friday | O12: 15:00 - 18:00 | P12: Monday | Q12: 09:00 - 12:00 | R12: We are traveling from the Czech Republic by bus together with another group of scouts and we are currently planning the bus, so we don't know the exact time of arrival. | S12: IST-92152 | T12: 525 | U12: Mollie | V12: 2025-01-24 10:58:50 | W12: 1737716330 | Z12: 4
A13: 70 | B13: Dana | C13: Tarantová | D13: komtesa.dana@gmail.com | E13: +420606227817 | F13: Junák - český skaut, středisko Oheň Most, z. s. Slovenského národního povstání 1191 434 01 Most IČ: 41324919 | G13: Czech Republic | H13: JUNAK - cesky skaut | I13: Junák - český skaut, středisko Oheň Most, z. s. | J13: 42501 | K13: Most | L13: 20 | M13: 4 | N13: Friday | O13: 15:00 - 18:00 | P13: Monday | Q13: 09:00 - 12:00 | S13: IST-15385 | T13: 600 | U13: Mollie | V13: 2025-01-26 18:36:08 | W13: 1737916569 | Z13: 3
A14: 71 | B14: Ondřej | C14: Mikulčík | D14: ondrej.mikulcik@gmail.com | E14: +420702282329 | F14: Junák Český skaut - středisko Vizovice z.s. Razov 761 Vizovice 76312 Czech republic IC: 46277404 | G14: Czech Republic | H14: JUNAK - cesky skaut | I14: Vizovice | J14: 724.12 | K14: Vizovice | L14: 13 | M14: 2 | N14: Friday | O14: 09:00 - 12:00 | P14: Monday | Q14: 09:00 - 12:00 | S14: IST-29006 | T14: 375 | U14: Mollie | V14: 2025-01-28 16:33:49 | W14: 1738082029 | Z14: 3
A15: 72 | B15: Vanda | C15: Hegerová | D15: vanda.hegerova@seznam.cz | E15: +420 | G15: Czech Republic | H15: JUNAK - cesky skaut | I15: Blaník | J15: 114.07 | K15: Prague | L15: 4 | M15: 1 | N15: Friday | O15: 15:00 - 18:00 | P15: Monday | Q15: 09:00 - 12:00 | R15: Arrival time is not exactly we are still planing. | S15: IST-81258 | T15: 125 | U15: Mollie | V15: 2025-01-28 19:14:48 | W15: 1738091688 | Z15: 4
A16: 73 | B16: Jonáš | C16: Novotný | D16: novotny.jonas@seznam.cz | E16: +420731403977 | G16: Czech Republic | H16: JUNAK - cesky skaut | I16: Anikrok a Dvojka | J16: 532.08 | K16: Přelouč | L16: 14 | M16: 4 | N16: Friday | O16: 12:00 - 15:00 | P16: Monday | Q16: 09:00 - 12:00 | S16: IST-95252 | T16: 450 | U16: Mollie | V16: 2025-01-28 19:30:24 | W16: 1738092624 | Z16: 3
A17: 75 | B17: Agáta | C17: Navrkalová | D17: agata.nvr@skaut.cz | E17: +420773301941 | G17: Czech Republic | H17: JUNAK - cesky skaut | I17: Junák - český skaut, středisko Podyjí Znojmo, z. s. | J17: 627.02 | K17: Znojmo | L17: 8 | M17: 2 | N17: Friday | O17: 09:00 - 12:00 | P17: Monday | Q17: 12:00 - 15:00 | S17: IST-18787 | T17: 250 | U17: Mollie | V17: 2025-01-31 10:36:55 | W17: 1738319816 | Z17: 3
A18: 76 | B18: Vlastimil | C18: Buriánek | D18: vlastimil.burianek@skaut.cz | E18: +420725561858 | G18: Czech Republic | H18: JUNAK - cesky skaut | I18: Děti přírody | J18: 713.02 | K18: Prostějov | L18: 9 | M18: 2 | N18: Friday | O18: 15:00 - 18:00 | P18: Monday | Q18: 12:00 - 15:00 | R18: Departure/arrival times are (still) approximate. | S18: IST-20023 | T18: 275 | U18: Mollie | V18: 2025-01-31 20:17:50 | W18: 1738354670 | Z18: 4
A19: 77 | B19: Ondřej | C19: Rejsek | D19: ondrej.rejsek@seznam.cz | E19: +420605211206 | F19: Junák - český skaut, středisko Želivák Hradec Králové, z. s. Čajkovského 1861/46A, 500 09 Hradec Králové IČO: 62693158 | G19: Czech Republic | H19: JUNAK - cesky skaut | I19: Želivák | J19: 526.07 | K19: Hradec Králové | L19: 12 | M19: 3 | N19: Friday | O19: 09:00 - 12:00 | P19: Monday | Q19: 09:00 - 12:00 | R19: We have exceeded the participant rate, because two of the leaders are still rangers in the age of 18, which want to go together. We would like to give them the opportunity to gain experience in leadership - to participate in organization of the international event. In our opinion they should have the support of older and experienced leader. Unfortunately the number of scout - participants is a little bit lower than expected. | S19: IST-64944 | T19: 375 | U19: Mollie | V19: 2025-01-31 20:55:09 | W19: 1738356909 | Z19: 2
A20: 78 | B20: Antonín | C20: Kala | D20: tonda.kala@seznam.cz | E20: +420603472473 | G20: Czech Republic | H20: JUNAK - cesky skaut | I20: Stopaři | J20: 118.52 | K20: Praha | L20: 14 | M20: 2 | N20: Friday | O20: 15:00 - 18:00 | P20: Monday | Q20: 12:00 - 15:00 | S20: IST-19283 | T20: 400 | U20: Mollie | V20: 2025-01-31 22:47:55 | W20: 1738363675 | Z20: 2
A21: 80 | B21: Jiří | C21: Granát | D21: namornik@skaut.cz | E21: +420732310218 | G21: Czech Republic | H21: JUNAK - cesky skaut | I21: Junák Kostelec nad Orlicí | J21: 524.03 | K21: Kostelec nad Orlicí | L21: 20 | M21: 4 | N21: Friday | O21: 09:00 - 12:00 | P21: Monday | Q21: 09:00 - 12:00 | S21: IST-23514 | T21: 600 | U21: Mollie | V21: 2025-02-01 21:53:16 | W21: 1738446796 | Z21: 2
A22: 82 | B22: Lucie | C22: Urbanová | D22: lucie.urbn@gmail.com | E22: +420728900846 | G22: Czech Republic | H22: JUNAK - cesky skaut | I22: Devítky | J22: 533.02 | K22: Litomyšl | L22: 8 | M22: 1 | N22: Friday | O22: 12:00 - 15:00 | P22: Monday | Q22: 12:00 - 15:00 | S22: IST-66761 | T22: 225 | U22: Mollie | V22: 2025-02-03 15:13:33 | W22: 1738595613 | Z22: 4
A23: 83 | B23: Kateřina | C23: Tuháčková | D23: katy58@skaut.cz | E23: +420725882920 | G23: Czech Republic | H23: JUNAK - cesky skaut | I23: Sluneční údolí | J23: 323.05.058 | K23: Starý Plzenec | L23: 8 | M23: 1 | N23: Friday | O23: 15:00 - 18:00 | P23: Monday | Q23: 09:00 - 12:00 | S23: IST-11470 | T23: 225 | U23: Mollie | V23: 2025-02-03 20:18:05 | W23: 1738613885 | Z23: 3
A24: 85 | B24: Jiří | C24: Nevřivý | D24: nevrivy.skaut@gmail.com | E24: +420736678622 | G24: Czech Republic | H24: JUNAK - cesky skaut | I24: Artemis/Ontario | J24: 724.06 | K24: Zlín-Malenovice | L24: 20 | M24: 4 | N24: Friday | O24: 15:00 - 18:00 | P24: Monday | Q24: 09:00 - 12:00 | S24: IST-97908 | T24: 600 | U24: Mollie | V24: 2025-02-04 22:26:15 | W24: 1738707976 | Z24: 4
A25: 100 | B25: Filip | C25: Fišer | D25: fiser-filip@seznam.cz | E25: +420731993016 | F25: Junák - český skaut, středisko Vamberk, z. s. Ič.: 42885311 V Lukách 598, 517 54 Vamberk | G25: Czech Republic | H25: JUNAK - cesky skaut | I25: 2. Oddíl (DSS) | J25: 524.09.002 | K25: Vamberk | L25: 6 | M25: 2 | N25: Friday | O25: 09:00 - 12:00 | P25: Monday | Q25: 09:00 - 12:00 | R25: the second leader Jaroslav Vašátko +420 733 580 760 jaroslav.vasatko@seznam.cz | S25: IST-21179 | T25: 200 | U25: Mollie | V25: 2025-02-07 14:42:26 | W25: 1738939346 | Z25: 1
A26: 101 | B26: Martin | C26: Matyáš | D26: matyasmartin0@gmail.com | E26: +420608642615 | G26: Czech Republic | H26: JUNAK - cesky skaut | I26: Tumulus Újezd u Brna aneb děcka, pecka, pojedeme do Německa | J26: 623.14 | K26: Újezd u Brna | L26: 5 | M26: 1 | N26: Friday | O26: 15:00 - 18:00 | P26: Monday | Q26: 12:00 - 15:00 | S26: IST-30049 | T26: 150 | U26: Mollie | V26: 2025-02-09 18:29:12 | W26: 1739125752 | Z26: 4
A27: 103 | B27: Bára | C27: Matoušová | D27: matousova.bara@skaut.cz | E27: +420605989853 | G27: Czech Republic | H27: JUNAK - cesky skaut | I27: Fata Morgana | J27: 523.1 | K27: Nové Město nad Metují | L27: 5 | M27: 1 | N27: Friday | O27: 09:00 - 12:00 | P27: Monday | Q27: 12:00 - 15:00 | S27: IST-64369 | T27: 150 | U27: Mollie | V27: 2025-02-10 13:55:50 | W27: 1739195751 | Z27: 2
A28: 104 | B28: Pavel | C28: Čechura | D28: pavelcechura@seznam.cz | E28: +420607927028 | G28: Czech Republic | H28: JUNAK - cesky skaut | I28: Třebechovice | J28: 521.01 | K28: Třebechovice pod Orebem | L28: 20 | M28: 4 | N28: Friday | O28: 09:00 - 12:00 | P28: Monday | Q28: 09:00 - 12:00 | S28: IST-84861 | T28: 600 | U28: Mollie | V28: 2025-02-10 16:39:41 | W28: 1739205581 | Z28: 2
A29: 105 | B29: Kateřina | C29: Čechová | D29: albus@skaut.cz | E29: +420602144407 | F29: Junák – český skaut, středisko Bílý los Praha, z. s. , Praha Liborova 470/2, Praha 6 – Břevnov, 16900 IČ: 61389650 | G29: Czech Republic | H29: JUNAK - cesky skaut | I29: Bílý los | J29: 116.33 | K29: Prague | L29: 6 | M29: 1 | N29: Friday | O29: 15:00 - 18:00 | P29: Monday | Q29: 12:00 - 15:00 | R29: Hello, we are not sure about out arrival and departure time, but I think we will be flexible about that. We are going to order bus with another few troops form our area. Greets, Katka Čechová - Albus. | S29: IST-15861 | T29: 175 | U29: Mollie | V29: 2025-02-10 18:13:21 | W29: 1739211201 | Z29: 3
A30: 106 | B30: Miroslav | C30: Král | D30: usteckadvojka@gmail.com | E30: +420605567227 | G30: Czech Republic | H30: JUNAK - cesky skaut | I30: Ústecká dvojka | J30: 427.01.002 | K30: Ústí nad Labem | L30: 20 | M30: 4 | N30: Friday | O30: 15:00 - 18:00 | P30: Monday | Q30: 09:00 - 12:00 | S30: IST-21250 | T30: 600 | U30: Mollie | V30: 2025-02-11 16:48:31 | W30: 1739292511 | Z30: 3
A31: 112 | B31: Michal | C31: Sýkora | D31: sykoramichal@skaut.cz | E31: +420739102827 | G31: Czech Republic | H31: JUNAK - cesky skaut | I31: AD FONTES | J31: 621.08 | K31: Šebrov - Kateřina | L31: 20 | M31: 4 | N31: Friday | O31: 09:00 - 12:00 | P31: Monday | Q31: 09:00 - 12:00 | S31: IST-54943 | T31: 600 | U31: Mollie | V31: 2025-02-17 21:05:42 | W31: 1739826342 | Z31: 2
A32: 127 | B32: Marie Anna | C32: Chlachulová | D32: mchlachulov.a@seznam.cz | E32: +420773883110 | G32: Czech Republic | H32: JUNAK - cesky skaut | I32: Mustangové | J32: 722.01 | K32: Uherské Hradiště | L32: 8 | M32: 2 | N32: Friday | O32: 15:00 - 18:00 | P32: Monday | Q32: 09:00 - 12:00 | R32: We have 2 leaders And 8 children, since we have both just turned 18 And we have no previous experience travelling with kids alone, we think it will be more responsible and safer to travel abroad with the kids with 2 leaders . | S32: IST-81116 | T32: 250 | U32: Mollie | V32: 2025-03-04 16:42:05 | W32: 1741106525 | Z32: 4
A33: 130 | B33: Mikuláš | C33: Jandík | D33: jandik.mikulasz@gmail.com | E33: +420731743330 | F33: Junák - český skaut, Středisko bratří Mašínů Praha z. s., Čihákova 1791/20, Praha 9, 190 00 | G33: Czech Republic | H33: JUNAK - cesky skaut | I33: Ginkgo | J33: 112.53 | K33: Praha | L33: 13 | M33: 2 | N33: Friday | O33: 18:00 - 21:00 | P33: Monday | Q33: 09:00 - 12:00 | R33: It is possible that we will arrive at a different time (during Friday afternoon or evening). | S33: IST-18827 | T33: 375 | U33: Mollie | V33: 2025-03-20 17:00:41 | W33: 1742490041 | Z33: 3
A34: 42 | B34: Lynn | C34: Millard | D34: lynn.millard@britishscoutingoverseas.org.uk | E34: +33637844303 | G34: GB | H34: BSO | I34: 1st Maisons-Laffitte International | J34: lynn burns nutrition | K34: Maisons-Laffitte | L34: 10 | M34: 3 | N34: Friday | O34: 21:00 - 00:00 | P34: Monday | Q34: 12:00 - 15:00 | R34: Partnering with 1st Prague Scouts as we are sharing equipment - Added extra leader but if not needed will let you know. We have potential requirement for additional adult for neurodivergent kids/support driving. Rather book one extra and cancel than the other way around. | S34: IST-11256 | T34: 325 | U34: Mollie | V34: 2024-12-04 19:36:32 | W34: 1733340992 | Z34: 2
A35: 57 | B35: Ulrich | C35: Maurach | D35: mail@ulrich-maurach.de | E35: +491713141429 | F35: Team! I’m a german father (born in HH) of a 14 year old daughter and made my promise as a British Scout in Celle, Lower Saxony (Niedersachsen) during the 80’s. A became a Venture Scout during that time and attended only one Intercamp – must have been near the river Rhine close to Bernkastel-Kues. This year I would like to attend the Intercamp, to show my daughter, what a wonderful movement scouting is. I do offer being a ‘helper’ during the event where ever it is needed. So – is it possible to attend with 1 tent and two persons? I hope to hear from you - Ulrich Ulrich Maurach M +49171 3141429 mail@ulrich-maurach.de | G35: GB | H35: BSO | I35: Ulrich Maurach | J35: -/- | K35: Berlin | L35: 1 | M35: 1 | N35: Friday | O35: 15:00 - 18:00 | P35: Monday | Q35: 12:00 - 15:00 | R35: Team! I’m a german father (born in HH) of a 14 year old daughter and made my promise as a British Scout in Celle, Lower Saxony (Niedersachsen) during the 80’s. A became a Venture Scout during that time and attended only one Intercamp – must have been near the river Rhine close to Bernkastel-Kues. This year I would like to attend the Intercamp, to show my daughter, what a wonderful movement scouting is. I do offer being a ‘helper’ during the event where ever it is needed. So – is it possible to attend with 1 tent and two persons? I hope to hear from you - Ulrich Ulrich Maurach M +49171 3141429 mail@ulrich-maurach.de | S35: IST-45306 | T35: 50 | U35: Mollie | V35: 2025-01-09 08:35:01 | W35: 1736411701 | Z35: 1
A36: 58 | B36: POGGIO | C36: STEPHAN | D36: poggio.stephan@yahoo.com | E36: +33632153653 | G36: France | H36: Scoutisme Français | I36: Scout du Florival | J36: EEDF - GUEBWILLER - SCOUTS DU FLORIVAL - 706019 | K36: Guebwiller - Soultz | L36: 21 | M36: 4 | N36: Friday | O36: 12:00 - 15:00 | P36: Monday | Q36: 09:00 - 12:00 | S36: IST-13515 | T36: 625 | U36: Mollie | V36: 2025-01-12 17:15:12 | W36: 1736702112 | Z36: 3
A37: 19 | B37: Caroline | C37: Pintsch | D37: caroline@pintsch.de | E37: +4915786783461 | G37: Germany | H37: Deutsche Pfadfinderschaft Sankt Georg | I37: DPSG Stamm Alzenau | J37: 2020329 | K37: Alzenau | L37: 17 | M37: 4 | N37: Friday | O37: 15:00 - 18:00 | P37: Monday | Q37: 12:00 - 15:00 | S37: IST-23477 | T37: 525 | U37: Mollie | V37: 2024-11-30 23:13:25 | W37: 1733008405 | Z37: 4
A38: 20 | B38: Jonas | C38: Spinczyk | D38: Jonas.spinczyk@rdp-bund.de | E38: +491621979714 | G38: Germany | H38: Deutsche Pfadfinderschaft Sankt Georg | I38: DPSG Kempen | J38: 01/02/12 | K38: Kempen | L38: 21 | M38: 5 | N38: Friday | O38: 15:00 - 18:00 | P38: Monday | Q38: 09:00 - 12:00 | R38: We need one more scout leader, because of a disabled participant. | S38: IST-11133 | T38: 650 | U38: Mollie | V38: 2024-11-30 23:17:00 | W38: 1733008620 | Z38: 2
A39: 22 | B39: Robin | C39: Bandini | D39: vorstand@pfadfinder-bammental.de | E39: +491627911091 | G39: Germany | H39: Deutsche Pfadfinderschaft Sankt Georg | I39: Stamm Karl Leisner | J39: 3363 | K39: Bammental | L39: 14 | M39: 3 | N39: Friday | O39: 18:00 - 21:00 | P39: Monday | Q39: 12:00 - 15:00 | S39: IST-11133 | T39: 425 | U39: Mollie | V39: 2024-11-30 23:33:26 | W39: 1733009606 | Z39: 1
A40: 23 | B40: Sebastian | C40: Kiwitt | D40: s-kiwitt@outlook.de | E40: +4917622228294 | F40: Sebastian Kiwitt DPSG Stamm St. Viktor Xanten Schwarzer Weg 10 46509 Xanten | G40: Germany | H40: Deutsche Pfadfinderschaft Sankt Georg | I40: DPSG Stamm St. Viktor Xanten | J40: 140101 | K40: Xanten | L40: 27 | M40: 7 | N40: Friday | O40: 12:00 - 15:00 | P40: Monday | Q40: 12:00 - 15:00 | R40: We need more Leeders, because we come with two Leeder by Car and the others with the Kids by Train. And I think Four Leeders with 27 Kids is not so safety. I hope this is Ok for you. Thank you. Best regards Sebastian | S40: IST-11133 | T40: 850 | U40: Mollie | V40: 2024-11-30 23:36:13 | W40: 1733009773 | Z40: 2
...

Sheet Subcamp 1
A1: No | B1: First name | C1: Last name | D1: Email | E1: Mobile phone | F1: Invoice details | G1: Country | H1: Scout Association | I1: Troop name | J1: Troop organisation number | K1: City | L1: Number of Children | M1: Number of Leaders | N1: Arrival day | O1: Arrival time | P1: Departure day | Q1: Departure time | R1: Further remarks (optional) | S1: Order Number | T1: Total Costs | U1: Payment Type | V1: Registration time | W1: Order Number2 | X1: Additional registrants | Y1: Comments RJ: | Z1: Subcamp
A2: {=_xlfn._xlws.FILTER('All Subcamps'!A2:Z139,'All Subcamps'!Z2:Z139=1)} -> 59 | B2: Barbora | C2: Jánská | D2: janskabarbora@gmail.com | E2: +420733650318 | F2: 0 | G2: Czech Republic | H2: JUNAK - cesky skaut | I2: Dráčata Štěnovice | J2: 323.02 | K2: Štěnovice | L2: 20 | M2: 4 | N2: Friday | O2: 18:00 - 21:00 | P2: Monday | Q2: 09:00 - 12:00 | R2: 0 | S2: IST-69112 | T2: 600 | U2: Mollie | V2: 2025-01-13 14:28:34 | W2: 1736778514 | X2: 0 | Y2: 0 | Z2: 1
A3: 65 | B3: Jan | C3: Holoubek | D3: jan.holoubek@skaut.cz | E3: +420736149229 | F3: 0 | G3: Czech Republic | H3: JUNAK - cesky skaut | I3: Stopa | J3: 526.06.004 | K3: Hradec Králové | L3: 6 | M3: 2 | N3: Friday | O3: 12:00 - 15:00 | P3: Monday | Q3: 09:00 - 12:00 | R3: We need to be two adults for safety reasons (two drivers). Also we both work with the troop during the year as mentors. | S3: IST-54674 | T3: 200 | U3: Mollie | V3: 2025-01-22 16:15:01 | W3: 1737562501 | X3: 0 | Y3: 0 | Z3: 1
A4: 66 | B4: Vojtěch | C4: Podzimek | D4: podzimek.vojta@skaut.cz | E4: +420724144345 | F4: Junák - český skaut, středisko Sopka Nová Paka, z. s. Svatojánská 1193 509 01 Nová Paka IČ: 60116421 | G4: Czech Republic | H4: JUNAK - cesky skaut | I4: Sopka Nová Paka | J4: 522.03 | K4: NOVÁ PAKA | L4: 20 | M4: 4 | N4: Friday | O4: 18:00 - 21:00 | P4: Monday | Q4: 09:00 - 12:00 | R4: 0 | S4: IST-16688 | T4: 600 | U4: Mollie | V4: 2025-01-22 20:56:18 | W4: 1737579378 | X4: 0 | Y4: 0 | Z4: 1
A5: 100 | B5: Filip | C5: Fišer | D5: fiser-filip@seznam.cz | E5: +420731993016 | F5: Junák - český skaut, středisko Vamberk, z. s. Ič.: 42885311 V Lukách 598, 517 54 Vamberk | G5: Czech Republic | H5: JUNAK - cesky skaut | I5: 2. Oddíl (DSS) | J5: 524.09.002 | K5: Vamberk | L5: 6 | M5: 2 | N5: Friday | O5: 09:00 - 12:00 | P5: Monday | Q5: 09:00 - 12:00 | R5: the second leader Jaroslav Vašátko +420 733 580 760 jaroslav.vasatko@seznam.cz | S5: IST-21179 | T5: 200 | U5: Mollie | V5: 2025-02-07 14:42:26 | W5: 1738939346 | X5: 0 | Y5: 0 | Z5: 1
A6: 57 | B6: Ulrich | C6: Maurach | D6: mail@ulrich-maurach.de | E6: +491713141429 | F6: Team! I’m a german father (born in HH) of a 14 year old daughter and made my promise as a British Scout in Celle, Lower Saxony (Niedersachsen) during the 80’s. A became a Venture Scout during that time and attended only one Intercamp – must have been near the river Rhine close to Bernkastel-Kues. This year I would like to attend the Intercamp, to show my daughter, what a wonderful movement scouting is. I do offer being a ‘helper’ during the event where ever it is needed. So – is it possible to attend with 1 tent and two persons? I hope to hear from you - Ulrich Ulrich Maurach M +49171 3141429 mail@ulrich-maurach.de | G6: GB | H6: BSO | I6: Ulrich Maurach | J6: -/- | K6: Berlin | L6: 1 | M6: 1 | N6: Friday | O6: 15:00 - 18:00 | P6: Monday | Q6: 12:00 - 15:00 | R6: Team! I’m a german father (born in HH) of a 14 year old daughter and made my promise as a British Scout in Celle, Lower Saxony (Niedersachsen) during the 80’s. A became a Venture Scout during that time and attended only one Intercamp – must have been near the river Rhine close to Bernkastel-Kues. This year I would like to attend the Intercamp, to show my daughter, what a wonderful movement scouting is. I do offer being a ‘helper’ during the event where ever it is needed. So – is it possible to attend with 1 tent and two persons? I hope to hear from you - Ulrich Ulrich Maurach M +49171 3141429 mail@ulrich-maurach.de | S6: IST-45306 | T6: 50 | U6: Mollie | V6: 2025-01-09 08:35:01 | W6: 1736411701 | X6: 0 | Y6: 0 | Z6: 1
A7: 22 | B7: Robin | C7: Bandini | D7: vorstand@pfadfinder-bammental.de | E7: +491627911091 | F7: 0 | G7: Germany | H7: Deutsche Pfadfinderschaft Sankt Georg | I7: Stamm Karl Leisner | J7: 3363 | K7: Bammental | L7: 14 | M7: 3 | N7: Friday | O7: 18:00 - 21:00 | P7: Monday | Q7: 12:00 - 15:00 | R7: 0 | S7: IST-11133 | T7: 425 | U7: Mollie | V7: 2024-11-30 23:33:26 | W7: 1733009606 | X7: 0 | Y7: 0 | Z7: 1
A8: 24 | B8: Martin | C8: Babst | D8: martin.babst@web.de | E8: +4915126957577 | F8: 0 | G8: Germany | H8: Deutsche Pfadfinderschaft Sankt Georg | I8: Maximilan Kolbe Lammersdorf | J8: 010607 | K8: Aachen | L8: 48 | M8: 9 | N8: Friday | O8: 12:00 - 15:00 | P8: Monday | Q8: 12:00 - 15:00 | R8: 0 | S8: IST-11133 | T8: 1425 | U8: Mollie | V8: 2024-12-01 00:20:50 | W8: 1733012451 | X8: 0 | Y8: 0 | Z8: 1
A9: 18 | B9: Nigel | C9: Fleetwood | D9: agsl2-6thgosport@gosportscouts.org.uk | E9: +447812674516 | F9: 6th Gosport Air Scout Group | G9: GB | H9: BSO | I9: 6th Gosport Air Scout Group | J9: 6th | K9: Gosport | L9: 17 | M9: 5 | N9: Friday | O9: 12:00 - 15:00 | P9: Monday | Q9: 12:00 - 15:00 | R9: 0 | S9: IST-11133 | T9: 550 | U9: Mollie | V9: 2024-11-30 23:11:03 | W9: 1733008263 | X9: 0 | Y9: 0 | Z9: 1
A10: 92 | B10: Patryk | C10: Konieczny | D10: patryk.konieczny@zhp.net.pl | E10: +48501679756 | F10: 0 | G10: Poland | H10: Zwiazek Harcerstwa Polskiego | I10: Czarne Siódemki | J10: 347 | K10: Cieszyn | L10: 12 | M10: 2 | N10: Friday | O10: 15:00 - 18:00 | P10: Monday | Q10: 09:00 - 12:00 | R10: We would like to be as close as possible on intercamp campsite to our friendly scout team called Watrzaki. Thanks in advance. | S10: IST-10906 | T10: 350 | U10: Mollie | V10: 2025-02-05 12:39:54 | W10: 1738759194 | X10: 0 | Y10: 0 | Z10: 1
A11: 110 | B11: Damian | C11: Wojciechowski | D11: damian.wojciechowski@zhp.net.pl | E11: +48530259321 | F11: 0 | G11: Poland | H11: Zwiazek Harcerstwa Polskiego | I11: 7 DH Arkana | J11: 7 | K11: Ząbki | L11: 15 | M11: 2 | N11: Friday | O11: 15:00 - 18:00 | P11: Monday | Q11: 09:00 - 12:00 | R11: 0 | S11: IST-20119 | T11: 425 | U11: Mollie | V11: 2025-02-16 21:44:20 | W11: 1739742260 | X11: 0 | Y11: 0 | Z11: 1
A12: 114 | B12: Emilia | C12: Skrzypek | D12: emilia.skrzypek@zhp.net.pl | E12: +48530259321 | F12: 0 | G12: Poland | H12: Zwiazek Harcerstwa Polskiego | I12: Czata wymiata | J12: 19 | K12: Mosina | L12: 15 | M12: 2 | N12: Friday | O12: 15:00 - 18:00 | P12: Monday | Q12: 09:00 - 12:00 | R12: 0 | S12: IST-96201 | T12: 425 | U12: Mollie | V12: 2025-02-23 18:30:20 | W12: 1740335420 | X12: 0 | Y12: 0 | Z12: 1
A13: 120 | B13: Izabela | C13: Kucmin-Bemelmans | D13: izabela.kucmin-bemelmans@zhp.net.pl | E13: +48692277074 | F13: 0 | G13: Poland | H13: Zwiazek Harcerstwa Polskiego | I13: Skalne Nietoperze | J13: 89 | K13: Biały Kościół | L13: 15 | M13: 2 | N13: Friday | O13: 15:00 - 18:00 | P13: Monday | Q13: 09:00 - 12:00 | R13: 0 | S13: IST-18955 | T13: 425 | U13: Mollie | V13: 2025-02-23 19:26:55 | W13: 1740338815 | X13: 0 | Y13: 0 | Z13: 1
A14: 121 | B14: Sabina | C14: Konieczny | D14: sabina.konieczny@zhp.net.pl | E14: +48 | F14: 0 | G14: Poland | H14: Zwiazek Harcerstwa Polskiego | I14: Watrzaki | J14: 25 | K14: Brenna | L14: 11 | M14: 1 | N14: Friday | O14: 18:00 - 21:00 | P14: Monday | Q14: 09:00 - 12:00 | R14: We come to intercamp with "Czarne Siódemki" team and we ask you to be together at the camp. | S14: IST-18013 | T14: 300 | U14: Mollie | V14: 2025-02-23 19:35:56 | W14: 1740339356 | X14: 0 | Y14: 0 | Z14: 1
A15: 13 | B15: Jorn | C15: Weijs | D15: jorn.weijs1997@live.nl | E15: +31620385792 | F15: 0 | G15: The Netherlands | H15: Scouting Nederland | I15: De Peelspeurders | J15: 1475 | K15: Venray | L15: 40 | M15: 8 | N15: Friday | O15: 12:00 - 15:00 | P15: Monday | Q15: 12:00 - 15:00 | R15: 0 | S15: IST-27230 | T15: 1200 | U15: Mollie | V15: 2024-11-30 20:01:30 | W15: 1732996890 | X15: 0 | Y15: 0 | Z15: 1
A16: 54 | B16: Marinus | C16: Hovius | D16: marinusfj@gmail.com | E16: +31641222084 | F16: 0 | G16: The Netherlands | H16: Scouting Nederland | I16: Scouting Den Oever | J16: 1234 | K16: Den Oever | L16: 25 | M16: 5 | N16: Friday | O16: 12:00 - 15:00 | P16: Monday | Q16: 12:00 - 15:00 | R16: 0 | S16: IST-13297 | T16: 750 | U16: Mollie | V16: 2024-12-20 13:03:49 | W16: 1734699829 | X16: 0 | Y16: 0 | Z16: 1
A17: 113 | B17: Rick | C17: Galeano | D17: rick_galeano@hotmail.com | E17: +491745407463 | F17: 0 | G17: United States | H17: Boy Scouts of America - Transatlantic Council | I17: Panzer Troop 44 | J17: 44 | K17: Boeblingen | L17: 10 | M17: 6 | N17: Friday | O17: 18:00 - 21:00 | P17: Monday | Q17: 09:00 - 12:00 | R17: 0 | S17: IST-17058 | T17: 400 | U17: Mollie | V17: 2025-02-23 17:37:11 | W17: 1740332231 | X17: 0 | Y17: 0 | Z17: 1
A18: 125 | B18: Roberto | C18: Baltazar | D18: bltzrr@gmail.com | E18: +494915117534988 | F18: 0 | G18: United States | H18: Boy Scouts of America - Transatlantic Council | I18: Radioactive | J18: 156 | K18: Ramstein | L18: 7 | M18: 3 | N18: Friday | O18: 18:00 - 21:00 | P18: Monday | Q18: 09:00 - 12:00 | R18: 0 | S18: IST-12623 | T18: 250 | U18: Mollie | V18: 2025-02-25 20:47:16 | W18: 1740516436 | X18: 0 | Y18: 0 | Z18: 1
A19: 132 | B19: Henry | C19: Williams | D19: tomnkt98@gmail.com | E19: +14104249248 | F19: 0 | G19: United States | H19: Boy Scouts of America - Transatlantic Council | I19: Scout Troop 154 (Boys) | J19: Troop 0154 (BT) | K19: Stuttgart | L19: 12 | M19: 3 | N19: Friday | O19: 12:00 - 15:00 | P19: Monday | Q19: 09:00 - 12:00 | R19: We also have a scout who paid with Troop 324, also from Stuttgart, but transferred to our troop. Please add that individual to our count so we are provided the correct number of camping slots, wristbands, patches, etc. Using three adults to assist with transportation of scouts and gear. Most of our scouts are on the the younger side, so the extra leader will help. | S19: IST-17804 | T19: 350 | U19: Mollie | V19: 2025-03-22 16:45:29 | W19: 1742661930 | X19: 0 | Y19: 0 | Z19: 1
L31: =SUM(L2:L20) -> 294 | M31: =SUM(M2:M20) -> 64 | N31: =L31+M31 -> 358

Sheet Subcamp 2
A1: No | B1: First name | C1: Last name | D1: Email | E1: Mobile phone | F1: Invoice details | G1: Country | H1: Scout Association | I1: Troop name | J1: Troop organisation number | K1: City | L1: Number of Children | M1: Number of Leaders | N1: Arrival day | O1: Arrival time | P1: Departure day | Q1: Departure time | R1: Further remarks (optional) | S1: Order Number | T1: Total Costs | U1: Payment Type | V1: Registration time | W1: Order Number2 | X1: Additional registrants | Y1: Comments RJ: | Z1: Subcamp
A2: {=_xlfn._xlws.FILTER('All Subcamps'!A2:Z139,'All Subcamps'!Z2:Z139=2)} -> 33 | B2: Joseph | C2: Monk | D2: joe.monk@britishscoutingoverseas.org.uk | E2: +32484266960 | F2: 0 | G2: Belgium | H2: FOS Open Scouting | I2: Central Brussels Scouts | J2: 112e | K2: Brussels | L2: 15 | M2: 5 | N2: Friday | O2: 21:00 - 00:00 | P2: Monday | Q2: 15:00 - 18:00 | R2: Arrival and Departure times are estimates. 2 additional Scouters needed due to logistical requirements to transport youth and equipment. | S2: IST-18979 | T2: 500 | U2: Mollie | V2: 2024-12-02 09:42:04 | W2: 1733132524 | X2: 0 | Y2: 0 | Z2: 2
A3: 30 | B3: Jonathan | C3: Copner | D3: jon.copner@britishscoutingoverseas.org.uk | E3: +32 | F3: Grootveldlaan 12, 3080 Tervuren, Belgium | G3: Belgium | H3: FOS Open Scouting | I3: Brussels Explorers | J3: FOS111 | K3: Tervuren | L3: 12 | M3: 3 | N3: Friday | O3: 18:00 - 21:00 | P3: Monday | Q3: 12:00 - 15:00 | R3: 3 leaders - 3 vehicles required | S3: IST-95976 | T3: 375 | U3: Mollie | V3: 2024-12-01 12:56:03 | W3: 1733057763 | X3: 0 | Y3: 0 | Z3: 2
A4: 62 | B4: Lenka | C4: Hechtová | D4: lenkalischkova@gmail.com | E4: +420607881402 | F4: 0 | G4: Czech Republic | H4: JUNAK - cesky skaut | I4: Core | J4: 511.02.004 | K4: Nový Bor | L4: 20 | M4: 4 | N4: Friday | O4: 18:00 - 21:00 | P4: Monday | Q4: 09:00 - 12:00 | R4: 0 | S4: IST-18688 | T4: 600 | U4: Mollie | V4: 2025-01-19 18:16:07 | W4: 1737310567 | X4: 0 | Y4: 0 | Z4: 2
A5: 63 | B5: Petr | C5: Kvarda | D5: kvardic.p@seznam.cz | E5: +420739528720 | F5: 0 | G5: Czech Republic | H5: JUNAK - cesky skaut | I5: Goliath | J5: 611.05 | K5: Přibyslav | L5: 8 | M5: 2 | N5: Friday | O5: 12:00 - 15:00 | P5: Monday | Q5: 15:00 - 18:00 | R5: 0 | S5: IST-12285 | T5: 250 | U5: Mollie | V5: 2025-01-20 17:26:18 | W5: 1737393978 | X5: 0 | Y5: 0 | Z5: 2
A6: 64 | B6: Klára | C6: Helánová | D6: akela.sebetov@skaut.cz | E6: +420777865883 | F6: Junák - Český skaut, středisko Severka, z.s. Šebetov 49 679 35 Czech Republic | G6: Czech Republic | H6: JUNAK - cesky skaut | I6: Středisko Severka | J6: 621.11 | K6: Šebetov | L6: 15 | M6: 3 | N6: Friday | O6: 15:00 - 18:00 | P6: Monday | Q6: 12:00 - 15:00 | R6: We are not sure about the arrival time yet. We're in the process of deciding between Friday morning (around 10 am) and evening (around 6 pm). We'll let you know once we've settled. | S6: IST-64335 | T6: 450 | U6: Mollie | V6: 2025-01-21 17:35:18 | W6: 1737480918 | X6: 0 | Y6: 0 | Z6: 2
A7: 77 | B7: Ondřej | C7: Rejsek | D7: ondrej.rejsek@seznam.cz | E7: +420605211206 | F7: Junák - český skaut, středisko Želivák Hradec Králové, z. s. Čajkovského 1861/46A, 500 09 Hradec Králové IČO: 62693158 | G7: Czech Republic | H7: JUNAK - cesky skaut | I7: Želivák | J7: 526.07 | K7: Hradec Králové | L7: 12 | M7: 3 | N7: Friday | O7: 09:00 - 12:00 | P7: Monday | Q7: 09:00 - 12:00 | R7: We have exceeded the participant rate, because two of the leaders are still rangers in the age of 18, which want to go together. We would like to give them the opportunity to gain experience in leadership - to participate in organization of the international event. In our opinion they should have the support of older and experienced leader. Unfortunately the number of scout - participants is a little bit lower than expected. | S7: IST-64944 | T7: 375 | U7: Mollie | V7: 2025-01-31 20:55:09 | W7: 1738356909 | X7: 0 | Y7: 0 | Z7: 2
A8: 78 | B8: Antonín | C8: Kala | D8: tonda.kala@seznam.cz | E8: +420603472473 | F8: 0 | G8: Czech Republic | H8: JUNAK - cesky skaut | I8: Stopaři | J8: 118.52 | K8: Praha | L8: 14 | M8: 2 | N8: Friday | O8: 15:00 - 18:00 | P8: Monday | Q8: 12:00 - 15:00 | R8: 0 | S8: IST-19283 | T8: 400 | U8: Mollie | V8: 2025-01-31 22:47:55 | W8: 1738363675 | X8: 0 | Y8: 0 | Z8: 2
A9: 80 | B9: Jiří | C9: Granát | D9: namornik@skaut.cz | E9: +420732310218 | F9: 0 | G9: Czech Republic | H9: JUNAK - cesky skaut | I9: Junák Kostelec nad Orlicí | J9: 524.03 | K9: Kostelec nad Orlicí | L9: 20 | M9: 4 | N9: Friday | O9: 09:00 - 12:00 | P9: Monday | Q9: 09:00 - 12:00 | R9: 0 | S9: IST-23514 | T9: 600 | U9: Mollie | V9: 2025-02-01 21:53:16 | W9: 1738446796 | X9: 0 | Y9: 0 | Z9: 2
A10: 103 | B10: Bára | C10: Matoušová | D10: matousova.bara@skaut.cz | E10: +420605989853 | F10: 0 | G10: Czech Republic | H10: JUNAK - cesky skaut | I10: Fata Morgana | J10: 523.1 | K10: Nové Město nad Metují | L10: 5 | M10: 1 | N10: Friday | O10: 09:00 - 12:00 | P10: Monday | Q10: 12:00 - 15:00 | R10: 0 | S10: IST-64369 | T10: 150 | U10: Mollie | V10: 2025-02-10 13:55:50 | W10: 1739195751 | X10: 0 | Y10: 0 | Z10: 2
A11: 104 | B11: Pavel | C11: Čechura | D11: pavelcechura@seznam.cz | E11: +420607927028 | F11: 0 | G11: Czech Republic | H11: JUNAK - cesky skaut | I11: Třebechovice | J11: 521.01 | K11: Třebechovice pod Orebem | L11: 20 | M11: 4 | N11: Friday | O11: 09:00 - 12:00 | P11: Monday | Q11: 09:00 - 12:00 | R11: 0 | S11: IST-84861 | T11: 600 | U11: Mollie | V11: 2025-02-10 16:39:41 | W11: 1739205581 | X11: 0 | Y11: 0 | Z11: 2
A12: 112 | B12: Michal | C12: Sýkora | D12: sykoramichal@skaut.cz | E12: +420739102827 | F12: 0 | G12: Czech Republic | H12: JUNAK - cesky skaut | I12: AD FONTES | J12: 621.08 | K12: Šebrov - Kateřina | L12: 20 | M12: 4 | N12: Friday | O12: 09:00 - 12:00 | P12: Monday | Q12: 09:00 - 12:00 | R12: 0 | S12: IST-54943 | T12: 600 | U12: Mollie | V12: 2025-02-17 21:05:42 | W12: 1739826342 | X12: 0 | Y12: 0 | Z12: 2
A13: 42 | B13: Lynn | C13: Millard | D13: lynn.millard@britishscoutingoverseas.org.uk | E13: +33637844303 | F13: 0 | G13: GB | H13: BSO | I13: 1st Maisons-Laffitte International | J13: lynn burns nutrition | K13: Maisons-Laffitte | L13: 10 | M13: 3 | N13: Friday | O13: 21:00 - 00:00 | P13: Monday | Q13: 12:00 - 15:00 | R13: Partnering with 1st Prague Scouts as we are sharing equipment - Added extra leader but if not needed will let you know. We have potential requirement for additional adult for neurodivergent kids/support driving. Rather book one extra and cancel than the other way around. | S13: IST-11256 | T13: 325 | U13: Mollie | V13: 2024-12-04 19:36:32 | W13: 1733340992 | X13: 0 | Y13: 0 | Z13: 2
A14: 20 | B14: Jonas | C14: Spinczyk | D14: Jonas.spinczyk@rdp-bund.de | E14: +491621979714 | F14: 0 | G14: Germany | H14: Deutsche Pfadfinderschaft Sankt Georg | I14: DPSG Kempen | J14: 01/02/12 | K14: Kempen | L14: 21 | M14: 5 | N14: Friday | O14: 15:00 - 18:00 | P14: Monday | Q14: 09:00 - 12:00 | R14: We need one more scout leader, because of a disabled participant. | S14: IST-11133 | T14: 650 | U14: Mollie | V14: 2024-11-30 23:17:00 | W14: 1733008620 | X14: 0 | Y14: 0 | Z14: 2
A15: 23 | B15: Sebastian | C15: Kiwitt | D15: s-kiwitt@outlook.de | E15: +4917622228294 | F15: Sebastian Kiwitt DPSG Stamm St. Viktor Xanten Schwarzer Weg 10 46509 Xanten | G15: Germany | H15: Deutsche Pfadfinderschaft Sankt Georg | I15: DPSG Stamm St. Viktor Xanten | J15: 140101 | K15: Xanten | L15: 27 | M15: 7 | N15: Friday | O15: 12:00 - 15:00 | P15: Monday | Q15: 12:00 - 15:00 | R15: We need more Leeders, because we come with two Leeder by Car and the others with the Kids by Train. And I think Four Leeders with 27 Kids is not so safety. I hope this is Ok for you. Thank you. Best regards Sebastian | S15: IST-11133 | T15: 850 | U15: Mollie | V15: 2024-11-30 23:36:13 | W15: 1733009773 | X15: 0 | Y15: 0 | Z15: 2
A16: 35 | B16: Lale | C16: Akman | D16: laleakman@yahoo.de | E16: +4917684098636 | F16: Eichendorffstraße 8, 68167 Mannheim | G16: Germany | H16: Deutsche Pfadfinderschaft Sankt Georg | I16: St. Bernhard | J16: 070101 | K16: Mannheim | L16: 15 | M16: 4 | N16: Friday | O16: 12:00 - 15:00 | P16: Monday | Q16: 15:00 - 18:00 | R16: 0 | S16: IST-17058 | T16: 475 | U16: Mollie | V16: 2024-12-02 18:01:18 | W16: 1733162478 | X16: 0 | Y16: 0 | Z16: 2
A17: 36 | B17: Fabian | C17: Berger | D17: bigberger@gmx.de | E17: +4917620771317 | F17: 0 | G17: Germany | H17: Deutsche Pfadfinderschaft Sankt Georg | I17: DPSG Stamm Cherusker | J17: 0007010300 | K17: Laudenbach | L17: 13 | M17: 2 | N17: Friday | O17: 15:00 - 18:00 | P17: Monday | Q17: 12:00 - 15:00 | R17: 0 | S17: IST-18820 | T17: 375 | U17: Mollie | V17: 2024-12-02 18:30:47 | W17: 1733164247 | X17: 0 | Y17: 0 | Z17: 2
A18: 37 | B18: Malte | C18: Grönemann | D18: malte.groenemann@dpsg-friedrichsfeld.de | E18: +4917641629411 | F18: 0 | G18: Germany | H18: Deutsche Pfadfinderschaft Sankt Georg | I18: DPSG St. Bonifatius Mannheim | J18: 070106 | K18: Mannheim | L18: 9 | M18: 2 | N18: Friday | O18: 18:00 - 21:00 | P18: Monday | Q18: 12:00 - 15:00 | R18: 0 | S18: IST-96584 | T18: 200 | U18: Mollie | V18: 2024-12-02 18:49:22 | W18: 1733165362 | X18: 0 | Y18: add. 3 kids | Z18: 2
A19: 38 | B19: Sven | C19: Mühlen | D19: sven@dpsgwegberg.de | E19: +4917696819125 | F19: DPSG Wegberg | G19: Germany | H19: Deutsche Pfadfinderschaft Sankt Georg | I19: DPSG Wegberg | J19: 0001041000 | K19: Wegberg | L19: 30 | M19: 6 | N19: Friday | O19: 18:00 - 21:00 | P19: Monday | Q19: 09:00 - 12:00 | R19: 0 | S19: IST-46593 | T19: 900 | U19: Mollie | V19: 2024-12-02 20:03:36 | W19: 1733169816 | X19: 0 | Y19: 0 | Z19: 2
A20: 21 | B20: Des | C20: Mahon | D20: des.mahon@arrowscouts.org.uk | E20: +447809149414 | F20: Des Mahon 3rd Chandlers Ford Scouts Arrow District | G20: GB | H20: British Guides In Foreign Countrys | I20: 3rd Chandler’s Ford | J20: 3rd | K20: Chandler’s Ford | L20: 6 | M20: 2 | N20: Friday | O20: 15:00 - 18:00 | P20: Monday | Q20: 09:00 - 12:00 | R20: Partnering with 1st Prague Scouts as we are sharing equipment | S20: IST-11133 | T20: 200 | U20: Mollie | V20: 2024-11-30 23:26:03 | W20: 1733009163 | X20: 0 | Y20: 0 | Z20: 2
A21: 17 | B21: Christopher | C21: Wait | D21: waitchris0103@gmail.com | E21: +420777216228 | F21: 1st Prague (Czech Republic) Scout Group z.s. – British Scouting Overseas Pod pekárnami 251/4, Vysočany, 190 00 Praha 9 ICO: 04755057 | G21: GB | H21: BSO | I21: 1st Prague Scouts | J21: 04755057 | K21: Prague | L21: 29 | M21: 6 | N21: Friday | O21: 09:00 - 12:00 | P21: Monday | Q21: 12:00 - 15:00 | R21: 0 | S21: IST-11133 | T21: 875 | U21: Mollie | V21: 2024-11-30 23:10:31 | W21: 1733008231 | X21: 0 | Y21: 0 | Z21: 2
A22: 49 | B22: Zuzana | C22: Holekova | D22: zuzanaholekova@centrum.sk | E22: +421905886516 | F22: 0 | G22: Slovakia | H22: Choose... | I22: Zbor Irmy Ševcechovej | J22: 31 | K22: Trenčianska Teplá | L22: 2 | M22: 1 | N22: Friday | O22: 15:00 - 18:00 | P22: Monday | Q22: 12:00 - 15:00 | R22: 0 | S22: IST-35004 | T22: 75 | U22: Mollie | V22: 2024-12-08 13:07:16 | W22: 1733663236 | X22: 0 | Y22: 0 | Z22: 2
A23: 44 | B23: Zuzana | C23: Holekova | D23: zuzanaholekova@centrum.sk | E23: +421905886516 | F23: 0 | G23: Slovakia | H23: Guests | I23: zbor Irmy Ševcechovej | J23: 31 | K23: Trenčianska Teplá | L23: 5 | M23: 1 | N23: Friday | O23: 15:00 - 18:00 | P23: Monday | Q23: 12:00 - 15:00 | R23: 0 | S23: IST-10569 | T23: 150 | U23: Mollie | V23: 2024-12-07 19:33:48 | W23: 1733600028 | X23: 0 | Y23: 0 | Z23: 2
A24: 96 | B24: Michał | C24: Wnuk | D24: michal.wnuk@zhp.net.pl | E24: +48602672459 | F24: 0 | G24: Poland | H24: Zwiazek Harcerstwa Polskiego | I24: Zawiercie 1 | J24: 1 | K24: Zawiercie | L24: 13 | M24: 2 | N24: Friday | O24: 15:00 - 18:00 | P24: Monday | Q24: 09:00 - 12:00 | R24: We ask that the camping area for the patrol "zawiercie 1" and "zawiercie 2" be next to each other. We are the same large group from one city. Would it be possible for us to spend the night on Thursday at the convention site? | S24: IST-63079 | T24: 375 | U24: Mollie | V24: 2025-02-05 14:21:53 | W24: 1738765313 | X24: 0 | Y24: 0 | Z24: 2
A25: 97 | B25: Katarzyna | C25: Krzepkowska | D25: hufiec@zawiercie.zhp.pl | E25: +48602672459 | F25: 0 | G25: Poland | H25: Zwiazek Harcerstwa Polskiego | I25: Zawiercie 2 | J25: 2 | K25: Zawiercie | L25: 13 | M25: 2 | N25: Friday | O25: 15:00 - 18:00 | P25: Monday | Q25: 09:00 - 12:00 | R25: We ask that the camping area for the patrol "zawiercie 1" and "zawiercie 2" be next to each other. We are the same large group from one city. Would it be possible for us to spend the night on Thursday at the convention site? | S25: IST-10147 | T25: 375 | U25: Mollie | V25: 2025-02-05 14:25:33 | W25: 1738765533 | X25: 0 | Y25: 0 | Z25: 2
A26: 98 | B26: Jacek | C26: Słaby | D26: jacek.slaby@zhp.net.pl | E26: +48502039396 | F26: 0 | G26: Poland | H26: Zwiazek Harcerstwa Polskiego | I26: 30 WDH | J26: 30 | K26: Warszawa | L26: 7 | M26: 1 | N26: Friday | O26: 15:00 - 18:00 | P26: Monday | Q26: 09:00 - 12:00 | R26: 0 | S26: IST-19825 | T26: 200 | U26: Mollie | V26: 2025-02-05 14:30:41 | W26: 1738765842 | X26: 0 | Y26: 0 | Z26: 2
A27: 99 | B27: Marta | C27: Zielińska | D27: marta.zielinska@zhp.net.pl | E27: +48535775774 | F27: 0 | G27: Poland | H27: Zwiazek Harcerstwa Polskiego | I27: 424 DS "Żywioły" | J27: 424 | K27: Izabelin | L27: 13 | M27: 2 | N27: Friday | O27: 18:00 - 21:00 | P27: Monday | Q27: 09:00 - 12:00 | R27: 0 | S27: IST-11217 | T27: 375 | U27: Mollie | V27: 2025-02-05 15:33:27 | W27: 1738769607 | X27: 0 | Y27: 0 | Z27: 2
A28: 108 | B28: Michał | C28: Święcicki | D28: michal.swiecicki@zhp.net.pl | E28: +48511267708 | F28: 0 | G28: Poland | H28: Zwiazek Harcerstwa Polskiego | I28: Granda | J28: 420 | K28: Warszawa | L28: 8 | M28: 2 | N28: Friday | O28: 18:00 - 21:00 | P28: Monday | Q28: 09:00 - 12:00 | R28: 0 | S28: IST-20570 | T28: 250 | U28: Mollie | V28: 2025-02-16 21:37:27 | W28: 1739741847 | X28: 0 | Y28: 0 | Z28: 2
A29: 109 | B29: Julia | C29: Kinderman | D29: julia.kinderman@zhp.net.pl | E29: +48519656858 | F29: 0 | G29: Poland | H29: Zwiazek Harcerstwa Polskiego | I29: Gwardians | J29: 96 | K29: Łódź | L29: 14 | M29: 2 | N29: Friday | O29: 12:00 - 15:00 | P29: Monday | Q29: 09:00 - 12:00 | R29: 0 | S29: IST-18637 | T29: 400 | U29: Mollie | V29: 2025-02-16 21:41:39 | W29: 1739742099 | X29: 0 | Y29: 0 | Z29: 2
A30: 115 | B30: Patrycja | C30: Kiryluk | D30: patrycja.kiryluk@zhp.net.pl | E30: +48 604948623 | F30: 0 | G30: Poland | H30: Zwiazek Harcerstwa Polskiego | I30: FDDH 2 | J30: 2 | K30: Morąg | L30: 15 | M30: 2 | N30: Friday | O30: 09:00 - 12:00 | P30: Monday | Q30: 09:00 - 12:00 | R30: We would be grateful if you could place our two teams, FDDH 1 and FDDH 2, in the same subcamp during the Intercamp. We don’t have enough equipment to divide between the teams, and we are part of the same scout group. | S30: IST-83825 | T30: 400 | U30: Mollie | V30: 2025-02-23 18:34:30 | W30: 1740335670 | X30: Plus 1 to pay | Y30: 0 | Z30: 2
A31: 116 | B31: Kamil | C31: Sagan | D31: kamil.sagan@zhp.net.pl | E31: +48795599749 | F31: 0 | G31: Poland | H31: Zwiazek Harcerstwa Polskiego | I31: HSDeserterzy | J31: 9 | K31: Kraków | L31: 10 | M31: 2 | N31: Friday | O31: 18:00 - 21:00 | P31: Monday | Q31: 09:00 - 12:00 | R31: 0 | S31: IST-16632 | T31: 300 | U31: Mollie | V31: 2025-02-23 18:38:33 | W31: 1740335913 | X31: 0 | Y31: 0 | Z31: 2
A32: 117 | B32: Jakub | C32: Jędras | D32: jakub.jedras@zhp.net.pl | E32: +48606891044 | F32: 0 | G32: Poland | H32: Zwiazek Harcerstwa Polskiego | I32: HSDeserterki | J32: 9 | K32: Kraków | L32: 5 | M32: 1 | N32: Friday | O32: 15:00 - 18:00 | P32: Monday | Q32: 09:00 - 12:00 | R32: 0 | S32: IST-17214 | T32: 150 | U32: Mollie | V32: 2025-02-23 18:44:55 | W32: 1740336295 | X32: 0 | Y32: 0 | Z32: 2
A33: 119 | B33: Dominik Jeffrey | C33: Rimaszauskas | D33: dominik.rimaszauskas@zhp.net.pl | E33: +48535037130 | F33: 0 | G33: Poland | H33: Zwiazek Harcerstwa Polskiego | I33: FDDH 1 | J33: 8 | K33: MORĄG | L33: 15 | M33: 2 | N33: Friday | O33: 15:00 - 18:00 | P33: Monday | Q33: 09:00 - 12:00 | R33: 0 | S33: IST-33514 | T33: 425 | U33: Mollie | V33: 2025-02-23 18:53:04 | W33: 1740336784 | X33: 0 | Y33: 0 | Z33: 2
A34: 136 | B34: Katarzyna | C34: Kwiatkowska | D34: katarzyna.kwiatkowska@zhp.net.pl | E34: +48 502601077 | F34: 0 | G34: Poland | H34: Zwiazek Harcerstwa Polskiego | I34: Włóczykije 1 | J34: 30 WDH | K34: Warszawa | L34: 7 | M34: 2 | N34: Friday | O34: 15:00 - 18:00 | P34: Monday | Q34: 09:00 - 12:00 | R34: 0 | S34: 0 | T34: 0 | U34: 0 | V34: 0 | W34: 0 | X34: 225 euro to be paid | Y34: 225 | Z34: 2
A35: 2 | B35: Frans | C35: Lenders | D35: franslenders@home.nl | E35: +31621857140 | F35: 0 | G35: The Netherlands | H35: Scouting Nederland | I35: St. Rumoldus | J35: 1454 | K35: Weert | L35: 16 | M35: 4 | N35: Friday | O35: 12:00 - 15:00 | P35: Monday | Q35: 12:00 - 15:00 | R35: 0 | S35: IST-75688 | T35: 500 | U35: Mollie | V35: 2024-11-30 19:07:13 | W35: 1732993633 | X35: 0 | Y35: 0 | Z35: 2
A36: 3 | B36: Arno | C36: van As | D36: arno.van.as@hotmail.com | E36: +31628679230 | F36: 0 | G36: The Netherlands | H36: Scouting Nederland | I36: Scouting Ewijk | J36: 1228 | K36: Ewijk | L36: 18 | M36: 5 | N36: Friday | O36: 12:00 - 15:00 | P36: Monday | Q36: 12:00 - 15:00 | R36: 0 | S36: IST-97382 | T36: 575 | U36: Mollie | V36: 2024-11-30 19:11:58 | W36: 1732993918 | X36: 0 | Y36: 0 | Z36: 2
A37: 4 | B37: Ricardo | C37: Laurens | D37: r.laurens.1995@gmail.com | E37: +31621642397 | F37: 0 | G37: The Netherlands | H37: Scouting Nederland | I37: St.Scouting Saffatin Maurik | J37: 1215 | K37: Maurik | L37: 12 | M37: 3 | N37: Friday | O37: 12:00 - 15:00 | P37: Monday | Q37: 12:00 - 15:00 | R37: 0 | S37: IST-85959 | T37: 375 | U37: Mollie | V37: 2024-11-30 19:14:24 | W37: 1732994065 | X37: 0 | Y37: 0 | Z37: 2
A38: 8 | B38: Peter | C38: de Graag | D38: peterdegraag@hotmail.com | E38: +31683644415 | F38: 0 | G38: The Netherlands | H38: Scouting Nederland | I38: Marnix van Sint Aldegonde | J38: 2085 | K38: Vlaardingen | L38: 5 | M38: 2 | N38: Friday | O38: 12:00 - 15:00 | P38: Monday | Q38: 12:00 - 15:00 | R38: 0 | S38: IST-15785 | T38: 175 | U38: Mollie | V38: 2024-11-30 19:45:35 | W38: 1732995935 | X38: 0 | Y38: 0 | Z38: 2
A39: 9 | B39: Frans | C39: Nieuwenhuys | D39: f.nieuwenhuys@gmail.com | E39: +31646337186 | F39: 0 | G39: The Netherlands | H39: Scouting Nederland | I39: Scouting St. Martinus | J39: 1606 | K39: Zaltbommel | L39: 7 | M39: 3 | N39: Friday | O39: 12:00 - 15:00 | P39: Monday | Q39: 12:00 - 15:00 | R39: 0 | S39: IST-21266 | T39: 250 | U39: Mollie | V39: 2024-11-30 19:48:36 | W39: 1732996116 | X39: 0 | Y39: 0 | Z39: 2
A40: 12 | B40: Joey | C40: Gelissen | D40: joeygelissen@outlook.com | E40: +31645816844 | F40: 0 | G40: The Netherlands | H40: Scouting Nederland | I40: Scouting St. Martinus Beek | J40: 1415 | K40: Beek (L) | L40: 29 | M40: 6 | N40: Friday | O40: 15:00 - 18:00 | P40: Monday | Q40: 12:00 - 15:00 | R40: 0 | S40: IST-10208 | T40: 875 | U40: Mollie | V40: 2024-11-30 19:59:14 | W40: 1732996754 | X40: 0 | Y40: 0 | Z40: 2
...

Sheet Subcamp 3
A1: No | B1: First name | C1: Last name | D1: Email | E1: Mobile phone | F1: Invoice details | G1: Country | H1: Scout Association | I1: Troop name | J1: Troop organisation number | K1: City | L1: Number of Children | M1: Number of Leaders | N1: Arrival day | O1: Arrival time | P1: Departure day | Q1: Departure time | R1: Further remarks (optional) | S1: Order Number | T1: Total Costs | U1: Payment Type | V1: Registration time | W1: Order Number2 | X1: Additional registrants | Y1: Comments RJ: | Z1: Subcamp
A2: {=_xlfn._xlws.FILTER('All Subcamps'!A2:Z139,'All Subcamps'!Z2:Z139=3)} -> 60 | B2: Martin | C2: Kolarik | D2: smurf@skaut.cz | E2: +420723923943 | F2: Junák – český skaut, středisko Járy Kaštila Prostějov, z. s. Sokolská 30, 796 01 Prostějov Czech republic IČO: 65762959 | G2: Czech Republic | H2: JUNAK - cesky skaut | I2: JK | J2: 713.05 | K2: Prostejov | L2: 20 | M2: 4 | N2: Friday | O2: 15:00 - 18:00 | P2: Monday | Q2: 09:00 - 12:00 | R2: 0 | S2: IST-11762 | T2: 600 | U2: Mollie | V2: 2025-01-15 07:08:46 | W2: 1736924926 | X2: 0 | Y2: 0 | Z2: 3
A3: 61 | B3: Pavel | C3: Šenkyřík | D3: 180.veneta@gmail.com | E3: +420733233486 | F3: Customer: Junák - český skaut, středisko Platan Praha, z. s. Adress: Viktorinova 1122/1,Praha 4 – Nusle, 140 00 Praha, Česká Republika IČO: 40613593 | G3: Czech Republic | H3: JUNAK - cesky skaut | I3: Platan | J3: 114.32 | K3: Prague | L3: 20 | M3: 3 | N3: Friday | O3: 18:00 - 21:00 | P3: Monday | Q3: 09:00 - 12:00 | R3: 0 | S3: IST-32540 | T3: 575 | U3: Mollie | V3: 2025-01-18 14:39:42 | W3: 1737211182 | X3: 0 | Y3: 0 | Z3: 3
A4: 70 | B4: Dana | C4: Tarantová | D4: komtesa.dana@gmail.com | E4: +420606227817 | F4: Junák - český skaut, středisko Oheň Most, z. s. Slovenského národního povstání 1191 434 01 Most IČ: 41324919 | G4: Czech Republic | H4: JUNAK - cesky skaut | I4: Junák - český skaut, středisko Oheň Most, z. s. | J4: 42501 | K4: Most | L4: 20 | M4: 4 | N4: Friday | O4: 15:00 - 18:00 | P4: Monday | Q4: 09:00 - 12:00 | R4: 0 | S4: IST-15385 | T4: 600 | U4: Mollie | V4: 2025-01-26 18:36:08 | W4: 1737916569 | X4: 0 | Y4: 0 | Z4: 3
A5: 71 | B5: Ondřej | C5: Mikulčík | D5: ondrej.mikulcik@gmail.com | E5: +420702282329 | F5: Junák Český skaut - středisko Vizovice z.s. Razov 761 Vizovice 76312 Czech republic IC: 46277404 | G5: Czech Republic | H5: JUNAK - cesky skaut | I5: Vizovice | J5: 724.12 | K5: Vizovice | L5: 13 | M5: 2 | N5: Friday | O5: 09:00 - 12:00 | P5: Monday | Q5: 09:00 - 12:00 | R5: 0 | S5: IST-29006 | T5: 375 | U5: Mollie | V5: 2025-01-28 16:33:49 | W5: 1738082029 | X5: 0 | Y5: 0 | Z5: 3
A6: 73 | B6: Jonáš | C6: Novotný | D6: novotny.jonas@seznam.cz | E6: +420731403977 | F6: 0 | G6: Czech Republic | H6: JUNAK - cesky skaut | I6: Anikrok a Dvojka | J6: 532.08 | K6: Přelouč | L6: 14 | M6: 4 | N6: Friday | O6: 12:00 - 15:00 | P6: Monday | Q6: 09:00 - 12:00 | R6: 0 | S6: IST-95252 | T6: 450 | U6: Mollie | V6: 2025-01-28 19:30:24 | W6: 1738092624 | X6: 0 | Y6: 0 | Z6: 3
A7: 75 | B7: Agáta | C7: Navrkalová | D7: agata.nvr@skaut.cz | E7: +420773301941 | F7: 0 | G7: Czech Republic | H7: JUNAK - cesky skaut | I7: Junák - český skaut, středisko Podyjí Znojmo, z. s. | J7: 627.02 | K7: Znojmo | L7: 8 | M7: 2 | N7: Friday | O7: 09:00 - 12:00 | P7: Monday | Q7: 12:00 - 15:00 | R7: 0 | S7: IST-18787 | T7: 250 | U7: Mollie | V7: 2025-01-31 10:36:55 | W7: 1738319816 | X7: 0 | Y7: 0 | Z7: 3
A8: 83 | B8: Kateřina | C8: Tuháčková | D8: katy58@skaut.cz | E8: +420725882920 | F8: 0 | G8: Czech Republic | H8: JUNAK - cesky skaut | I8: Sluneční údolí | J8: 323.05.058 | K8: Starý Plzenec | L8: 8 | M8: 1 | N8: Friday | O8: 15:00 - 18:00 | P8: Monday | Q8: 09:00 - 12:00 | R8: 0 | S8: IST-11470 | T8: 225 | U8: Mollie | V8: 2025-02-03 20:18:05 | W8: 1738613885 | X8: 0 | Y8: 0 | Z8: 3
A9: 105 | B9: Kateřina | C9: Čechová | D9: albus@skaut.cz | E9: +420602144407 | F9: Junák – český skaut, středisko Bílý los Praha, z. s. , Praha Liborova 470/2, Praha 6 – Břevnov, 16900 IČ: 61389650 | G9: Czech Republic | H9: JUNAK - cesky skaut | I9: Bílý los | J9: 116.33 | K9: Prague | L9: 6 | M9: 1 | N9: Friday | O9: 15:00 - 18:00 | P9: Monday | Q9: 12:00 - 15:00 | R9: Hello, we are not sure about out arrival and departure time, but I think we will be flexible about that. We are going to order bus with another few troops form our area. Greets, Katka Čechová - Albus. | S9: IST-15861 | T9: 175 | U9: Mollie | V9: 2025-02-10 18:13:21 | W9: 1739211201 | X9: 0 | Y9: 0 | Z9: 3
A10: 106 | B10: Miroslav | C10: Král | D10: usteckadvojka@gmail.com | E10: +420605567227 | F10: 0 | G10: Czech Republic | H10: JUNAK - cesky skaut | I10: Ústecká dvojka | J10: 427.01.002 | K10: Ústí nad Labem | L10: 20 | M10: 4 | N10: Friday | O10: 15:00 - 18:00 | P10: Monday | Q10: 09:00 - 12:00 | R10: 0 | S10: IST-21250 | T10: 600 | U10: Mollie | V10: 2025-02-11 16:48:31 | W10: 1739292511 | X10: 0 | Y10: 0 | Z10: 3
A11: 130 | B11: Mikuláš | C11: Jandík | D11: jandik.mikulasz@gmail.com | E11: +420731743330 | F11: Junák - český skaut, Středisko bratří Mašínů Praha z. s., Čihákova 1791/20, Praha 9, 190 00 | G11: Czech Republic | H11: JUNAK - cesky skaut | I11: Ginkgo | J11: 112.53 | K11: Praha | L11: 13 | M11: 2 | N11: Friday | O11: 18:00 - 21:00 | P11: Monday | Q11: 09:00 - 12:00 | R11: It is possible that we will arrive at a different time (during Friday afternoon or evening). | S11: IST-18827 | T11: 375 | U11: Mollie | V11: 2025-03-20 17:00:41 | W11: 1742490041 | X11: 0 | Y11: 0 | Z11: 3
A12: 58 | B12: POGGIO | C12: STEPHAN | D12: poggio.stephan@yahoo.com | E12: +33632153653 | F12: 0 | G12: France | H12: Scoutisme Français | I12: Scout du Florival | J12: EEDF - GUEBWILLER - SCOUTS DU FLORIVAL - 706019 | K12: Guebwiller - Soultz | L12: 21 | M12: 4 | N12: Friday | O12: 12:00 - 15:00 | P12: Monday | Q12: 09:00 - 12:00 | R12: 0 | S12: IST-13515 | T12: 625 | U12: Mollie | V12: 2025-01-12 17:15:12 | W12: 1736702112 | X12: 0 | Y12: 0 | Z12: 3
A13: 25 | B13: Daniela | C13: Kouril | D13: daniela@cityscouts.org | E13: +491605807584 | F13: Falls Julia vom Dorp dieses Jahr in einem Subcampteam ist, möchten wir gerne in ihr Subcamp. Sie ist Leiterin in unserem Stamm. | G13: Germany | H13: Deutsche Pfadfinderschaft Sankt Georg | I13: Stamm Cityscouts | J13: 010304 | K13: Mönchengladbach | L13: 27 | M13: 6 | N13: Friday | O13: 12:00 - 15:00 | P13: Monday | Q13: 12:00 - 15:00 | R13: 0 | S13: IST-11133 | T13: 825 | U13: Mollie | V13: 2024-12-01 00:21:33 | W13: 1733012493 | X13: 0 | Y13: 0 | Z13: 3
A14: 26 | B14: Jan | C14: Van den Brakel | D14: jbrl@cbs.nl | E14: +31 | F14: I will pay via banktransfer. | G14: Germany | H14: Deutsche Pfadfinderschaft Sankt Georg | I14: St Nikolaus Gangelt | J14: 010403 | K14: Gangelt | L14: 12 | M14: 4 | N14: Friday | O14: 12:00 - 15:00 | P14: Monday | Q14: 12:00 - 15:00 | R14: WE need four leaders for transportation. | S14: IST-41645 | T14: 400 | U14: Mollie | V14: 2024-12-01 09:32:32 | W14: 1733045552 | X14: 0 | Y14: 0 | Z14: 3
A15: 28 | B15: Katharina | C15: Wenderott | D15: k.wenderott@paderborn.com | E15: +4915750634181 | F15: Pastoralbüro An St. Marien DPSG Phönix Bonn Heerstraße 128 53111 Bonn lea@dpsg-phoenix.net | G15: Germany | H15: Deutsche Pfadfinderschaft Sankt Georg | I15: DPSG Phönix Bonn | J15: 10/12/03 | K15: Bonn | L15: 26 | M15: 6 | N15: Friday | O15: 18:00 - 21:00 | P15: Monday | Q15: 09:00 - 12:00 | R15: 0 | S15: IST-13423 | T15: 800 | U15: Mollie | V15: 2024-12-01 12:09:38 | W15: 1733054978 | X15: 0 | Y15: 0 | Z15: 3
A16: 29 | B16: Sarah | C16: Corres | D16: corres.sarah@gmx.de | E16: +491754170858 | F16: 0 | G16: Germany | H16: Deutsche Pfadfinderschaft Sankt Georg | I16: Pfadfinder Erkelenz | J16: 010413 | K16: Erkelenz | L16: 25 | M16: 5 | N16: Friday | O16: 15:00 - 18:00 | P16: Monday | Q16: 09:00 - 12:00 | R16: 0 | S16: IST-17411 | T16: 750 | U16: Mollie | V16: 2024-12-01 12:15:33 | W16: 1733055333 | X16: 0 | Y16: 0 | Z16: 3
A17: 34 | B17: Svenja | C17: Walter | D17: svenjawalter95@web.de | E17: +491741021155 | F17: 0 | G17: Germany | H17: Deutsche Pfadfinderschaft Sankt Georg | I17: DPSG Obertürkheim Stamm St. Franziskus | J17: 19/01/01 | K17: Stuttgart | L17: 5 | M17: 3 | N17: Friday | O17: 12:00 - 15:00 | P17: Monday | Q17: 12:00 - 15:00 | R17: 0 | S17: IST-10640 | T17: 200 | U17: Mollie | V17: 2024-12-02 10:28:28 | W17: 1733135308 | X17: 0 | Y17: 0 | Z17: 3
A18: 39 | B18: Fabian | C18: Dietzmann | D18: fabian.dietzmann@gmail.com | E18: +4917643431461 | F18: 0 | G18: Germany | H18: Deutsche Pfadfinderschaft Sankt Georg | I18: Stamm von Berg | J18: 0010010100 | K18: Solingen | L18: 22 | M18: 5 | N18: Friday | O18: 15:00 - 18:00 | P18: Monday | Q18: 09:00 - 12:00 | R18: 0 | S18: IST-31582 | T18: 675 | U18: Mollie | V18: 2024-12-02 21:07:13 | W18: 1733173633 | X18: 0 | Y18: 0 | Z18: 3
A19: 46 | B19: Annika | C19: Tobies | D19: an@tobies.info | E19: +4915734650329 | F19: DPSG St. Rochus Rochusstraße 223 53123 Bonn Germany | G19: Germany | H19: Deutsche Pfadfinderschaft Sankt Georg | I19: DPSG St. Rochus | J19: Pfadfinder | K19: Bonn | L19: 9 | M19: 3 | N19: Friday | O19: 15:00 - 18:00 | P19: Monday | Q19: 12:00 - 15:00 | R19: Hello, we've got two boys in our troop that have diagnosis in the field of adhd and autism that we want to include in our group activities. To do this we need to increase the number of leaders. We are looking forward to this Intercamp! Cheers Annika | S19: IST-17682 | T19: 300 | U19: Mollie | V19: 2024-12-07 20:38:29 | W19: 1733603909 | X19: 0 | Y19: 0 | Z19: 3
A20: 16 | B20: Vladimir | C20: Bilek | D20: v.bilek@email.cz | E20: +352621277044 | F20: same as above | G20: Luxembourg | H20: Guests | I20: Telstar scouts international | J20: 12345 | K20: Luxembourg | L20: 30 | M20: 5 | N20: Friday | O20: 18:00 - 21:00 | P20: Monday | Q20: 09:00 - 12:00 | R20: 0 | S20: IST-23477 | T20: 875 | U20: Mollie | V20: 2024-11-30 23:10:24 | W20: 1733008224 | X20: 0 | Y20: 0 | Z20: 3
A21: 139 | B21: András | C21: Imregh | D21: 0 | E21: 0 | F21: 0 | G21: Hungary | H21: Magyar Cserkészszövetség | I21: 0 | J21: 0 | K21: Budapest | L21: 12 | M21: 5 | N21: Friday | O21: 15:00 - 18:00 | P21: Monday | Q21: 09:00 - 12:00 | R21: 0 | S21: 0 | T21: 0 | U21: 0 | V21: 0 | W21: 0 | X21: 575 euro to be paid | Y21: 575 | Z21: 3
